Workbook

Sheet Definations
A1: x5 | B1: 1
A4: x | B4: x2 | C4: a
A5: Project Communications Management Terms | B5: Acknowledgment | C5: Acknowledgment The receiver signals that the message has been received. An acknowledgment shows receipt of the message, but not necessarily agreement with the message.
B6: active listening | C6: Active listening The receiver confirms that the message is being received through feedback, questions, prompts for clarity, and other signs of confirmation.
B7: Choice of media | C7: Choice of media The best modality to use when communicating that is relevant to the information being communicated.
B8: Communication assumptions | C8: Communication assumptions Anything that the project management team believes to be true but hasn’t proven to be true. For example, the project management team may assume that all of the project team can be reached via cell phone, but parts of the world, as of this writing, don’t have a cell signal.
B9: Communication barrier | C9: Communication barrier Anything that prohibits communication from occurring.
B10: Communication channels formula | C10: Communication channels formula N(N – 1)/2, where N represents the number of identified stakeholders. This formula reveals the total number of communication channels within a project.
B11: Communication constraints | C11: Communication constraints Anything that limits the project management team’s options. When it comes to communication constraints, geographical locales, incompatible communications software, and even limited communications technology can constrain the project team.
B12: Communications management plan | C12: Communications management plan A project management subsidiary plan that defines the stakeholders who need specific information, the person who will supply the information, the schedule for the information to be supplied, and the approved modality to provide the information.
B13: Decoder | C13: Decoder The device that decodes a message as it is being received.
B14: Effective listening | C14: Effective listening The receiver is involved in the listening experience by paying attention to visual cues from the speaker and paralingual characteristics, and by asking relevant questions. Encoder The device that encodes the message being sent.
B15: Feedback | C15: Feedback The sender confirms that the receiver understands the message by directly asking for a response, questions for clarification, or other confirmation.
B16: Influence/impact grid | C16: Influence/impact grid Stakeholders are mapped on a grid based on their influence over the project in relation to their influence over the project execution.
B17: Information presentation tools | C17: Information presentation tools A software package that allows the project management team to present the project’s health through graphics, spreadsheets, and text. (Think of Microsoft Project.)
... B30: Push communication | C30: Push communication This approach pushes the information from the sender to the receiver without any real acknowledgment that the information was really received or understood. Consider letters, faxes, voicemail messages, e-mails, and other communications modalities that the sender packages and sends to receivers through some intermediary network. Receiver The person who receives the message. Sender The person who is sending the message. Sender–receiver models Feedback loops and barriers to communications. Stakeholder notifications Notices to the stakeholders about resolved issues, approved changes, and the overall health of the project. Status review meeting A regularly scheduled meeting to discuss the status of the project and its progress toward completing the project scope statement. Time reporting system A system to record the actual time to complete project activities.
A31: Project Cost Management Terms | B31: Cost variance (CV) | C31: Cost variance (CV) The difference of the earned value amount and the cumulative actual costs of the project. The formula is CV = EV – AC.
B32: Definitive estimate | C32: Definitive estimate This estimate type is one of the most accurate. It’s used late in the planning processes and is associated with bottomup estimating. You need the WBS in order to create the definitive estimate. The range of variance for the estimate can be from –5 percent to +10 percent.
B33: Direct costs | C33: Direct costs Costs are attributed directly to the project work and cannot be shared among projects (for example, airfare, hotels, long-distance phone charges, and so on).
B34: Earned value (EV) | C34: Earned value (EV) Earned value is the physical work completed to date and the authorized budget for that work. It is the percentage of the BAC that represents the actual work completed in the project.
B35: Estimate at completion (EAC) | C35: Estimate at completion (EAC) These forecasting formulas predict the likely completed costs of the project based on current scenarios within the project.
B36: Estimate to complete (ETC) | C36: Estimate to complete (ETC) An earned value management formula that predicts how much funding the project will require to be completed. Three variations of this formula are based on conditions the project may be experiencing.
B37: Fixed costs | C37: Fixed costs Costs that remain constant throughout the life of the project (the cost of a piece of rented equipment for the project, the cost of a consultant brought on to the project, and so on).
B38: Funding limit reconciliation | C38: Funding limit reconciliation An organization’s approach to managing cash flow against the project deliverables based on a schedule, milestone accomplishment, or data constraints.
B39: Indirect costs | C39: Indirect costs Costs that are representative of more than one project (for example, utilities for the performing organization, access to a training room, project management software license, and so on).
B40: Known unknown | C40: Known unknown An event that will likely happen within the project, but when it will happen and to what degree is unknown. These events, such as delays, are usually risk-related.
B41: Learning curve | C41: Learning curve An approach that assumes the cost per unit decreases the more units workers complete, because workers learn as they complete the required work.
B42: Oligopoly | C42: Oligopoly A market condition where the market is so tight that the actions of one vendor affect the actions of all the others.
B43: Opportunity cost | C43: Opportunity cost The total cost of the opportunity that is refused to realize an opposing opportunity.
... B79: Work package | C79: Work package The smallest item in the work breakdown structure. Cost aggregation Costs are parallel to each WBS work package. The costs of each work package are aggregated to their corresponding control accounts. Each control account then is aggregated to the sum of the project costs. Cost baseline A time-lapse exposure of when the project monies are to be spent in relation to cumulative values of the work completed in the project. Cost budgeting The cost aggregation achieved by assigning specific dollar amounts for each of the scheduled activities or, more likely, for each of the work packages in the WBS. Cost budgeting applies the cost estimates over time. Cost change control system A system that examines any changes associated with scope changes, the cost of materials, and the cost of any other resources, and the associated impact on the overall project cost. Cost management plan The cost management plan dictates how cost variances will be managed. Cost of poor quality The monies spent to recover from not adhering to the expected level of quality. Examples may include rework, defect repair, loss of life or limb because safety precautions were not taken, loss of sales, and loss of customers. This is also known as the cost of nonconformance to quality. Cost of quality The monies spent to attain the expected level of quality within a project. Examples include training, testing, and safety precautions. Cost performance index (CPI) Measures the project based on its financial performance. The formula is CPI = EV/AC.
A80: Project Integration Management Terms | B80: Assumption log | C80: Assumption log An assumption is something that is believed to be true or false, but it has not yet been proven to be true or false. Assumptions that prove wrong can become risks for the project. All identified project assumptions are recorded in the assumption log for testing and analysis, and the outcomes are recorded.
B81: Benefit/cost ratio (BCR) models | C81: Benefit/cost ratio (BCR) models This is an example of a benefits comparison model. It examines the benefit-to-cost ratio.
B82: Change control board (CCB) | C82: Change control board (CCB) A committee that evaluates the worthiness of a proposed change and either approves or rejects the proposed change.
B83: Change control system (CCS) | C83: Change control system (CCS) The change control system communicates the process for controlling changes to the project deliverables. This system works with the configuration management system and seeks to control and document proposals to change the project’s product.
B84: Change log | C84: Change log All changes that enter into a project are recorded in the change log. The characteristics of the change, such as the time, cost, risk, and scope details, are also recorded.
B85: Change management plan | C85: Change management plan This plan details the project procedures for entertaining change requests: how change requests are managed, documented, approved, or declined.
B86: Closure processes | C86: Closure processes This final process group of the project management life cycle is responsible for closing the project phase or project. This is where project documentation is archived and project contracts are also closed.
B87: Communications management plan | C87: Communications management plan This plan defines who will get what information, how they will receive it, and in what modality the communication will take place.
B88: Configuration identification | C88: Configuration identification This includes the labeling of the components, how changes are made to the product, and the accountability of the changes.
B89: Configuration management plan | C89: Configuration management plan This plan is an input to the control scope process. It defines how changes to the features and functions of the project deliverable, the product scope, may enter the project.
...

Sheet Data
A1: x | B1: x | C1: x | D1: x | E1: x | F1: x | G1: x | H1: 1 | I1: 2 | J1: 3 | K1: 4 | L1: 5 | M1: 6 | N1: 7 | O1: 8 | P1: 9 | Q1: 10 | R1: 11 | S1: 12 | T1: 13 | U1: 14 | V1: 15 | W1: a
A2: x | B2: 1 | C2: Project Management Fundamental Terms | D2: Project Management Fundamental Terms | E2: =LEN(D2) -> 36 | F2: x | G2: x | H2: x | I2: x | J2: x
A3: =C3=D3 -> FALSE | B3: =B2+1 -> 2 | C3: Project Management Fundamental Terms | D3: A Guide to the Project Management Body of Knowledge (PMBOK Guide) | E3: =LEN(D3) -> 65 | F3: 1 | G3: =IF(F3=1,1,G2+1) -> 1 | H3: =IF($G3=H$1,$D3,"") -> A Guide to the Project Management Body of Knowledge (PMBOK Guide) | I3: =IF($G4=I$1,$D4,"") -> The PMI publication that defines widely accepted project management practices. The CAPM and the PMP exam are based on this book. | J3: =IF($G5=J$1,$D5,"") | K3: =IF($G6=K$1,$D6,"") | L3: =IF($G7=L$1,$D7,"") | M3: =IF($G8=M$1,$D8,"") | N3: =IF($G9=N$1,$D9,"") | O3: =IF($G10=O$1,$D10,"") | P3: =IF($G11=P$1,$D11,"") | Q3: =IF($G12=Q$1,$D12,"") | R3: =IF($G13=R$1,$D13,"") | S3: =IF($G14=S$1,$D14,"") | T3: =IF($G15=T$1,$D15,"") | U3: =IF($G16=U$1,$D16,"") | V3: =IF($G17=V$1,$D17,"") | W3: =CONCATENATE(H3," ",I3," ",J3," ",K3," ",L3," ",M3," ",N3," ",O3," ",P3," ",Q3," ",R3," ",S3," ",T3," ",U3," ",V3) -> A Guide to the Project Management Body of Knowledge (PMBOK Guide) The PMI publication that defines widely accepted project management practices. The CAPM and the PMP exam are based on this book.
A4: =C4=D4 -> FALSE | B4: =B3+1 -> 3 | C4: Project Management Fundamental Terms | D4: The PMI publication that defines widely accepted project management practices. The CAPM and the PMP exam are based on this book. | E4: =LEN(D4) -> 128 | G4: =IF(F4=1,1,G3+1) -> 2 | H4: =IF($G4=H$1,$D4,"") | I4: =IF($G5=I$1,$D5,"") | J4: =IF($G6=J$1,$D6,"") | K4: =IF($G7=K$1,$D7,"") | L4: =IF($G8=L$1,$D8,"") | M4: =IF($G9=M$1,$D9,"") | N4: =IF($G10=N$1,$D10,"") | O4: =IF($G11=O$1,$D11,"") | P4: =IF($G12=P$1,$D12,"") | Q4: =IF($G13=Q$1,$D13,"") | R4: =IF($G14=R$1,$D14,"") | S4: =IF($G15=S$1,$D15,"") | T4: =IF($G16=T$1,$D16,"") | U4: =IF($G17=U$1,$D17,"") | V4: =IF($G18=V$1,$D18,"") | W4: =CONCATENATE(H4," ",I4," ",J4," ",K4," ",L4," ",M4," ",N4," ",O4," ",P4," ",Q4," ",R4," ",S4," ",T4," ",U4," ",V4)
A5: =C5=D5 -> FALSE | B5: =B4+1 -> 4 | C5: Project Management Fundamental Terms | D5: Application areas | E5: =LEN(D5) -> 17 | F5: 1 | G5: =IF(F5=1,1,G4+1) -> 1 | H5: =IF($G5=H$1,$D5,"") -> Application areas | I5: =IF($G6=I$1,$D6,"") -> The areas of expertise, industry, or function where a project is centered. Examples of application areas include architecture, IT, health care, and manufacturing. | J5: =IF($G7=J$1,$D7,"") | K5: =IF($G8=K$1,$D8,"") | L5: =IF($G9=L$1,$D9,"") | M5: =IF($G10=M$1,$D10,"") | N5: =IF($G11=N$1,$D11,"") | O5: =IF($G12=O$1,$D12,"") | P5: =IF($G13=P$1,$D13,"") | Q5: =IF($G14=Q$1,$D14,"") | R5: =IF($G15=R$1,$D15,"") | S5: =IF($G16=S$1,$D16,"") | T5: =IF($G17=T$1,$D17,"") | U5: =IF($G18=U$1,$D18,"") | V5: =IF($G19=V$1,$D19,"") | W5: =CONCATENATE(H5," ",I5," ",J5," ",K5," ",L5," ",M5," ",N5," ",O5," ",P5," ",Q5," ",R5," ",S5," ",T5," ",U5," ",V5) -> Application areas The areas of expertise, industry, or function where a project is centered. Examples of application areas include architecture, IT, health care, and manufacturing.
A6: =C6=D6 -> FALSE | B6: =B5+1 -> 5 | C6: Project Management Fundamental Terms | D6: The areas of expertise, industry, or function where a project is centered. Examples of application areas include architecture, IT, health care, and manufacturing. | E6: =LEN(D6) -> 162 | G6: =IF(F6=1,1,G5+1) -> 2 | H6: =IF($G6=H$1,$D6,"") | I6: =IF($G7=I$1,$D7,"") | J6: =IF($G8=J$1,$D8,"") | K6: =IF($G9=K$1,$D9,"") | L6: =IF($G10=L$1,$D10,"") | M6: =IF($G11=M$1,$D11,"") | N6: =IF($G12=N$1,$D12,"") | O6: =IF($G13=O$1,$D13,"") | P6: =IF($G14=P$1,$D14,"") | Q6: =IF($G15=Q$1,$D15,"") | R6: =IF($G16=R$1,$D16,"") | S6: =IF($G17=S$1,$D17,"") | T6: =IF($G18=T$1,$D18,"") | U6: =IF($G19=U$1,$D19,"") | V6: =IF($G20=V$1,$D20,"") | W6: =CONCATENATE(H6," ",I6," ",J6," ",K6," ",L6," ",M6," ",N6," ",O6," ",P6," ",Q6," ",R6," ",S6," ",T6," ",U6," ",V6)
A7: =C7=D7 -> FALSE | B7: =B6+1 -> 6 | C7: Project Management Fundamental Terms | D7: Business value | E7: =LEN(D7) -> 14 | F7: 1 | G7: =IF(F7=1,1,G6+1) -> 1 | H7: =IF($G7=H$1,$D7,"") -> Business value | I7: =IF($G8=I$1,$D8,"") -> A quantifiable return on investment. The return can be tangible, such as equipment, money, or market share. The return can also be intangible, such as brand recognition, trademarks, and reputation. | J7: =IF($G9=J$1,$D9,"") | K7: =IF($G10=K$1,$D10,"") | L7: =IF($G11=L$1,$D11,"") | M7: =IF($G12=M$1,$D12,"") | N7: =IF($G13=N$1,$D13,"") | O7: =IF($G14=O$1,$D14,"") | P7: =IF($G15=P$1,$D15,"") | Q7: =IF($G16=Q$1,$D16,"") | R7: =IF($G17=R$1,$D17,"") | S7: =IF($G18=S$1,$D18,"") | T7: =IF($G19=T$1,$D19,"") | U7: =IF($G20=U$1,$D20,"") | V7: =IF($G21=V$1,$D21,"") | W7: =CONCATENATE(H7," ",I7," ",J7," ",K7," ",L7," ",M7," ",N7," ",O7," ",P7," ",Q7," ",R7," ",S7," ",T7," ",U7," ",V7) -> Business value A quantifiable return on investment. The return can be tangible, such as equipment, money, or market share. The return can also be intangible, such as brand recognition, trademarks, and reputation.
A8: =C8=D8 -> FALSE | B8: =B7+1 -> 7 | C8: Project Management Fundamental Terms | D8: A quantifiable return on investment. The return can be tangible, such as equipment, money, or market share. The return can also be intangible, such as brand recognition, trademarks, and reputation. | E8: =LEN(D8) -> 197 | G8: =IF(F8=1,1,G7+1) -> 2 | H8: =IF($G8=H$1,$D8,"") | I8: =IF($G9=I$1,$D9,"") | J8: =IF($G10=J$1,$D10,"") | K8: =IF($G11=K$1,$D11,"") | L8: =IF($G12=L$1,$D12,"") | M8: =IF($G13=M$1,$D13,"") | N8: =IF($G14=N$1,$D14,"") | O8: =IF($G15=O$1,$D15,"") | P8: =IF($G16=P$1,$D16,"") | Q8: =IF($G17=Q$1,$D17,"") | R8: =IF($G18=R$1,$D18,"") | S8: =IF($G19=S$1,$D19,"") | T8: =IF($G20=T$1,$D20,"") | U8: =IF($G21=U$1,$D21,"") | V8: =IF($G22=V$1,$D22,"") | W8: =CONCATENATE(H8," ",I8," ",J8," ",K8," ",L8," ",M8," ",N8," ",O8," ",P8," ",Q8," ",R8," ",S8," ",T8," ",U8," ",V8)
A9: =C9=D9 -> FALSE | B9: =B8+1 -> 8 | C9: Project Management Fundamental Terms | D9: Certified Associate in Project Management (CAPM) | E9: =LEN(D9) -> 48 | F9: 1 | G9: =IF(F9=1,1,G8+1) -> 1 | H9: =IF($G9=H$1,$D9,"") -> Certified Associate in Project Management (CAPM) | I9: =IF($G10=I$1,$D10,"") -> A person who has slightly less project management experience than a PMP, but who has qualified for and then passed the CAPM examination. | J9: =IF($G11=J$1,$D11,"") | K9: =IF($G12=K$1,$D12,"") | L9: =IF($G13=L$1,$D13,"") | M9: =IF($G14=M$1,$D14,"") | N9: =IF($G15=N$1,$D15,"") | O9: =IF($G16=O$1,$D16,"") | P9: =IF($G17=P$1,$D17,"") | Q9: =IF($G18=Q$1,$D18,"") | R9: =IF($G19=R$1,$D19,"") | S9: =IF($G20=S$1,$D20,"") | T9: =IF($G21=T$1,$D21,"") | U9: =IF($G22=U$1,$D22,"") | V9: =IF($G23=V$1,$D23,"") | W9: =CONCATENATE(H9," ",I9," ",J9," ",K9," ",L9," ",M9," ",N9," ",O9," ",P9," ",Q9," ",R9," ",S9," ",T9," ",U9," ",V9) -> Certified Associate in Project Management (CAPM) A person who has slightly less project management experience than a PMP, but who has qualified for and then passed the CAPM examination.
A10: =C10=D10 -> FALSE | B10: =B9+1 -> 9 | C10: Project Management Fundamental Terms | D10: A person who has slightly less project management experience than a PMP, but who has qualified for and then passed the CAPM examination. | E10: =LEN(D10) -> 136 | G10: =IF(F10=1,1,G9+1) -> 2 | H10: =IF($G10=H$1,$D10,"") | I10: =IF($G11=I$1,$D11,"") | J10: =IF($G12=J$1,$D12,"") | K10: =IF($G13=K$1,$D13,"") | L10: =IF($G14=L$1,$D14,"") | M10: =IF($G15=M$1,$D15,"") | N10: =IF($G16=N$1,$D16,"") | O10: =IF($G17=O$1,$D17,"") | P10: =IF($G18=P$1,$D18,"") | Q10: =IF($G19=Q$1,$D19,"") | R10: =IF($G20=R$1,$D20,"") | S10: =IF($G21=S$1,$D21,"") | T10: =IF($G22=T$1,$D22,"") | U10: =IF($G23=U$1,$D23,"") | V10: =IF($G24=V$1,$D24,"") | W10: =CONCATENATE(H10," ",I10," ",J10," ",K10," ",L10," ",M10," ",N10," ",O10," ",P10," ",Q10," ",R10," ",S10," ",T10," ",U10," ",V10)
A11: =C11=D11 -> FALSE | B11: =B10+1 -> 10 | C11: Project Management Fundamental Terms | D11: Cultural and social environment | E11: =LEN(D11) -> 31 | F11: 1 | G11: =IF(F11=1,1,G10+1) -> 1 | H11: =IF($G11=H$1,$D11,"") -> Cultural and social environment | I11: =IF($G12=I$1,$D12,"") -> Defines how a project affects people and how those people may affect the project. Cultural and social environments include the economic, educational, ethical, religious, demographic, and ethnic composition of the people affected by the project. | J11: =IF($G13=J$1,$D13,"") | K11: =IF($G14=K$1,$D14,"") | L11: =IF($G15=L$1,$D15,"") | M11: =IF($G16=M$1,$D16,"") | N11: =IF($G17=N$1,$D17,"") | O11: =IF($G18=O$1,$D18,"") | P11: =IF($G19=P$1,$D19,"") | Q11: =IF($G20=Q$1,$D20,"") | R11: =IF($G21=R$1,$D21,"") | S11: =IF($G22=S$1,$D22,"") | T11: =IF($G23=T$1,$D23,"") | U11: =IF($G24=U$1,$D24,"") | V11: =IF($G25=V$1,$D25,"") | W11: =CONCATENATE(H11," ",I11," ",J11," ",K11," ",L11," ",M11," ",N11," ",O11," ",P11," ",Q11," ",R11," ",S11," ",T11," ",U11," ",V11) -> Cultural and social environment Defines how a project affects people and how those people may affect the project. Cultural and social environments include the economic, educational, ethical, religious, demographic, and ethnic composition of the people affected by the project.
A12: =C12=D12 -> FALSE | B12: =B11+1 -> 11 | C12: Project Management Fundamental Terms | D12: Defines how a project affects people and how those people may affect the project. Cultural and social environments include the economic, educational, ethical, religious, demographic, and ethnic composition of the people affected by the project. | E12: =LEN(D12) -> 244 | G12: =IF(F12=1,1,G11+1) -> 2 | H12: =IF($G12=H$1,$D12,"") | I12: =IF($G13=I$1,$D13,"") | J12: =IF($G14=J$1,$D14,"") | K12: =IF($G15=K$1,$D15,"") | L12: =IF($G16=L$1,$D16,"") | M12: =IF($G17=M$1,$D17,"") | N12: =IF($G18=N$1,$D18,"") | O12: =IF($G19=O$1,$D19,"") | P12: =IF($G20=P$1,$D20,"") | Q12: =IF($G21=Q$1,$D21,"") | R12: =IF($G22=R$1,$D22,"") | S12: =IF($G23=S$1,$D23,"") | T12: =IF($G24=T$1,$D24,"") | U12: =IF($G25=U$1,$D25,"") | V12: =IF($G26=V$1,$D26,"") | W12: =CONCATENATE(H12," ",I12," ",J12," ",K12," ",L12," ",M12," ",N12," ",O12," ",P12," ",Q12," ",R12," ",S12," ",T12," ",U12," ",V12)
A13: =C13=D13 -> FALSE | B13: =B12+1 -> 12 | C13: Project Management Fundamental Terms | D13: Deliverable | E13: =LEN(D13) -> 11 | F13: 1 | G13: =IF(F13=1,1,G12+1) -> 1 | H13: =IF($G13=H$1,$D13,"") -> Deliverable | I13: =IF($G14=I$1,$D14,"") -> A product, service, or result created by a project. Projects can have multiple deliverables. | J13: =IF($G15=J$1,$D15,"") | K13: =IF($G16=K$1,$D16,"") | L13: =IF($G17=L$1,$D17,"") | M13: =IF($G18=M$1,$D18,"") | N13: =IF($G19=N$1,$D19,"") | O13: =IF($G20=O$1,$D20,"") | P13: =IF($G21=P$1,$D21,"") | Q13: =IF($G22=Q$1,$D22,"") | R13: =IF($G23=R$1,$D23,"") | S13: =IF($G24=S$1,$D24,"") | T13: =IF($G25=T$1,$D25,"") | U13: =IF($G26=U$1,$D26,"") | V13: =IF($G27=V$1,$D27,"") | W13: =CONCATENATE(H13," ",I13," ",J13," ",K13," ",L13," ",M13," ",N13," ",O13," ",P13," ",Q13," ",R13," ",S13," ",T13," ",U13," ",V13) -> Deliverable A product, service, or result created by a project. Projects can have multiple deliverables.
A14: =C14=D14 -> FALSE | B14: =B13+1 -> 13 | C14: Project Management Fundamental Terms | D14: A product, service, or result created by a project. Projects can have multiple deliverables. | E14: =LEN(D14) -> 92 | G14: =IF(F14=1,1,G13+1) -> 2 | H14: =IF($G14=H$1,$D14,"") | I14: =IF($G15=I$1,$D15,"") | J14: =IF($G16=J$1,$D16,"") | K14: =IF($G17=K$1,$D17,"") | L14: =IF($G18=L$1,$D18,"") | M14: =IF($G19=M$1,$D19,"") | N14: =IF($G20=N$1,$D20,"") | O14: =IF($G21=O$1,$D21,"") | P14: =IF($G22=P$1,$D22,"") | Q14: =IF($G23=Q$1,$D23,"") | R14: =IF($G24=R$1,$D24,"") | S14: =IF($G25=S$1,$D25,"") | T14: =IF($G26=T$1,$D26,"") | U14: =IF($G27=U$1,$D27,"") | V14: =IF($G28=V$1,$D28,"") | W14: =CONCATENATE(H14," ",I14," ",J14," ",K14," ",L14," ",M14," ",N14," ",O14," ",P14," ",Q14," ",R14," ",S14," ",T14," ",U14," ",V14)
A15: =C15=D15 -> FALSE | B15: =B14+1 -> 14 | C15: Project Management Fundamental Terms | D15: General management skills | E15: =LEN(D15) -> 25 | F15: 1 | G15: =IF(F15=1,1,G14+1) -> 1 | H15: =IF($G15=H$1,$D15,"") -> General management skills | I15: =IF($G16=I$1,$D16,"") -> These include the application of accounting, procurement, sales and marketing, contracting, manufacturing, logistics, strategic planning, human resource management, standards and regulations, and information technology. | J15: =IF($G17=J$1,$D17,"") -> International and political environment | K15: =IF($G18=K$1,$D18,"") -> The consideration of the local and international laws, languages, communication challenges, time zone differences, and other non-collocated issues that affect a project’s ability to progress. | L15: =IF($G19=L$1,$D19,"") | M15: =IF($G20=M$1,$D20,"") | N15: =IF($G21=N$1,$D21,"") | O15: =IF($G22=O$1,$D22,"") | P15: =IF($G23=P$1,$D23,"") | Q15: =IF($G24=Q$1,$D24,"") | R15: =IF($G25=R$1,$D25,"") | S15: =IF($G26=S$1,$D26,"") | T15: =IF($G27=T$1,$D27,"") | U15: =IF($G28=U$1,$D28,"") | V15: =IF($G29=V$1,$D29,"") | W15: =CONCATENATE(H15," ",I15," ",J15," ",K15," ",L15," ",M15," ",N15," ",O15," ",P15," ",Q15," ",R15," ",S15," ",T15," ",U15," ",V15) -> General management skills These include the application of accounting, procurement, sales and marketing, contracting, manufacturing, logistics, strategic planning, human resource management, standards and regulations, and information technology. International and political environment The consideration of the local and international laws, languages, communication challenges, time zone differences, and other non-collocated issues that affect a project’s ability to progress.
A16: =C16=D16 -> FALSE | B16: =B15+1 -> 15 | C16: Project Management Fundamental Terms | D16: These include the application of accounting, procurement, sales and marketing, contracting, manufacturing, logistics, strategic planning, human resource management, standards and regulations, and information technology. | E16: =LEN(D16) -> 219 | G16: =IF(F16=1,1,G15+1) -> 2 | H16: =IF($G16=H$1,$D16,"") | I16: =IF($G17=I$1,$D17,"") | J16: =IF($G18=J$1,$D18,"") | K16: =IF($G19=K$1,$D19,"") | L16: =IF($G20=L$1,$D20,"") | M16: =IF($G21=M$1,$D21,"") | N16: =IF($G22=N$1,$D22,"") | O16: =IF($G23=O$1,$D23,"") | P16: =IF($G24=P$1,$D24,"") | Q16: =IF($G25=Q$1,$D25,"") | R16: =IF($G26=R$1,$D26,"") | S16: =IF($G27=S$1,$D27,"") | T16: =IF($G28=T$1,$D28,"") | U16: =IF($G29=U$1,$D29,"") | V16: =IF($G30=V$1,$D30,"") | W16: =CONCATENATE(H16," ",I16," ",J16," ",K16," ",L16," ",M16," ",N16," ",O16," ",P16," ",Q16," ",R16," ",S16," ",T16," ",U16," ",V16)
A17: =C17=D17 -> FALSE | B17: =B16+1 -> 16 | C17: Project Management Fundamental Terms | D17: International and political environment | E17: =LEN(D17) -> 39 | G17: =IF(F17=1,1,G16+1) -> 3 | H17: =IF($G17=H$1,$D17,"") | I17: =IF($G18=I$1,$D18,"") | J17: =IF($G19=J$1,$D19,"") | K17: =IF($G20=K$1,$D20,"") | L17: =IF($G21=L$1,$D21,"") | M17: =IF($G22=M$1,$D22,"") | N17: =IF($G23=N$1,$D23,"") | O17: =IF($G24=O$1,$D24,"") | P17: =IF($G25=P$1,$D25,"") | Q17: =IF($G26=Q$1,$D26,"") | R17: =IF($G27=R$1,$D27,"") | S17: =IF($G28=S$1,$D28,"") | T17: =IF($G29=T$1,$D29,"") | U17: =IF($G30=U$1,$D30,"") | V17: =IF($G31=V$1,$D31,"") | W17: =CONCATENATE(H17," ",I17," ",J17," ",K17," ",L17," ",M17," ",N17," ",O17," ",P17," ",Q17," ",R17," ",S17," ",T17," ",U17," ",V17)
A18: =C18=D18 -> FALSE | B18: =B17+1 -> 17 | C18: Project Management Fundamental Terms | D18: The consideration of the local and international laws, languages, communication challenges, time zone differences, and other non-collocated issues that affect a project’s ability to progress. | E18: =LEN(D18) -> 191 | G18: =IF(F18=1,1,G17+1) -> 4 | H18: =IF($G18=H$1,$D18,"") | I18: =IF($G19=I$1,$D19,"") | J18: =IF($G20=J$1,$D20,"") | K18: =IF($G21=K$1,$D21,"") | L18: =IF($G22=L$1,$D22,"") | M18: =IF($G23=M$1,$D23,"") | N18: =IF($G24=N$1,$D24,"") | O18: =IF($G25=O$1,$D25,"") | P18: =IF($G26=P$1,$D26,"") | Q18: =IF($G27=Q$1,$D27,"") | R18: =IF($G28=R$1,$D28,"") | S18: =IF($G29=S$1,$D29,"") | T18: =IF($G30=T$1,$D30,"") | U18: =IF($G31=U$1,$D31,"") | V18: =IF($G32=V$1,$D32,"") | W18: =CONCATENATE(H18," ",I18," ",J18," ",K18," ",L18," ",M18," ",N18," ",O18," ",P18," ",Q18," ",R18," ",S18," ",T18," ",U18," ",V18)
A19: =C19=D19 -> FALSE | B19: =B18+1 -> 18 | C19: Project Management Fundamental Terms | D19: Interpersonal skills | E19: =LEN(D19) -> 20 | F19: 1 | G19: =IF(F19=1,1,G18+1) -> 1 | H19: =IF($G19=H$1,$D19,"") -> Interpersonal skills | I19: =IF($G20=I$1,$D20,"") -> The ability to interact, lead, motivate, and manage people. | J19: =IF($G21=J$1,$D21,"") | K19: =IF($G22=K$1,$D22,"") | L19: =IF($G23=L$1,$D23,"") | M19: =IF($G24=M$1,$D24,"") | N19: =IF($G25=N$1,$D25,"") | O19: =IF($G26=O$1,$D26,"") | P19: =IF($G27=P$1,$D27,"") | Q19: =IF($G28=Q$1,$D28,"") | R19: =IF($G29=R$1,$D29,"") | S19: =IF($G30=S$1,$D30,"") | T19: =IF($G31=T$1,$D31,"") | U19: =IF($G32=U$1,$D32,"") | V19: =IF($G33=V$1,$D33,"") | W19: =CONCATENATE(H19," ",I19," ",J19," ",K19," ",L19," ",M19," ",N19," ",O19," ",P19," ",Q19," ",R19," ",S19," ",T19," ",U19," ",V19) -> Interpersonal skills The ability to interact, lead, motivate, and manage people.
A20: =C20=D20 -> FALSE | B20: =B19+1 -> 19 | C20: Project Management Fundamental Terms | D20: The ability to interact, lead, motivate, and manage people. | E20: =LEN(D20) -> 59 | G20: =IF(F20=1,1,G19+1) -> 2 | H20: =IF($G20=H$1,$D20,"") | I20: =IF($G21=I$1,$D21,"") | J20: =IF($G22=J$1,$D22,"") | K20: =IF($G23=K$1,$D23,"") | L20: =IF($G24=L$1,$D24,"") | M20: =IF($G25=M$1,$D25,"") | N20: =IF($G26=N$1,$D26,"") | O20: =IF($G27=O$1,$D27,"") | P20: =IF($G28=P$1,$D28,"") | Q20: =IF($G29=Q$1,$D29,"") | R20: =IF($G30=R$1,$D30,"") | S20: =IF($G31=S$1,$D31,"") | T20: =IF($G32=T$1,$D32,"") | U20: =IF($G33=U$1,$D33,"") | V20: =IF($G34=V$1,$D34,"") | W20: =CONCATENATE(H20," ",I20," ",J20," ",K20," ",L20," ",M20," ",N20," ",O20," ",P20," ",Q20," ",R20," ",S20," ",T20," ",U20," ",V20)
A21: =C21=D21 -> FALSE | B21: =B20+1 -> 20 | C21: Project Management Fundamental Terms | D21: Iron Triangle of Project Management | E21: =LEN(D21) -> 35 | F21: 1 | G21: =IF(F21=1,1,G20+1) -> 1 | H21: =IF($G21=H$1,$D21,"") -> Iron Triangle of Project Management | I21: =IF($G22=I$1,$D22,"") -> A triangle with the characteristics of time, cost, and scope. Time, cost, and scope each constitute one side of the triangle; if any side of the Iron Triangle is not in balance with the other sides, the project will suffer. The Iron Triangle of Project Management is also known as the Triple Constraints of Project Management, as all projects are constrained by time, cost, and scope. | J21: =IF($G23=J$1,$D23,"") | K21: =IF($G24=K$1,$D24,"") | L21: =IF($G25=L$1,$D25,"") | M21: =IF($G26=M$1,$D26,"") | N21: =IF($G27=N$1,$D27,"") | O21: =IF($G28=O$1,$D28,"") | P21: =IF($G29=P$1,$D29,"") | Q21: =IF($G30=Q$1,$D30,"") | R21: =IF($G31=R$1,$D31,"") | S21: =IF($G32=S$1,$D32,"") | T21: =IF($G33=T$1,$D33,"") | U21: =IF($G34=U$1,$D34,"") | V21: =IF($G35=V$1,$D35,"") | W21: =CONCATENATE(H21," ",I21," ",J21," ",K21," ",L21," ",M21," ",N21," ",O21," ",P21," ",Q21," ",R21," ",S21," ",T21," ",U21," ",V21) -> Iron Triangle of Project Management A triangle with the characteristics of time, cost, and scope. Time, cost, and scope each constitute one side of the triangle; if any side of the Iron Triangle is not in balance with the other sides, the project will suffer. The Iron Triangle of Project Management is also known as the Triple Constraints of Project Management, as all projects are constrained by time, cost, and scope.
A22: =C22=D22 -> FALSE | B22: =B21+1 -> 21 | C22: Project Management Fundamental Terms | D22: A triangle with the characteristics of time, cost, and scope. Time, cost, and scope each constitute one side of the triangle; if any side of the Iron Triangle is not in balance with the other sides, the project will suffer. The Iron Triangle of Project Management is also known as the Triple Constraints of Project Management, as all projects are constrained by time, cost, and scope. | E22: =LEN(D22) -> 384 | G22: =IF(F22=1,1,G21+1) -> 2 | H22: =IF($G22=H$1,$D22,"") | I22: =IF($G23=I$1,$D23,"") | J22: =IF($G24=J$1,$D24,"") | K22: =IF($G25=K$1,$D25,"") | L22: =IF($G26=L$1,$D26,"") | M22: =IF($G27=M$1,$D27,"") | N22: =IF($G28=N$1,$D28,"") | O22: =IF($G29=O$1,$D29,"") | P22: =IF($G30=P$1,$D30,"") | Q22: =IF($G31=Q$1,$D31,"") | R22: =IF($G32=R$1,$D32,"") | S22: =IF($G33=S$1,$D33,"") | T22: =IF($G34=T$1,$D34,"") | U22: =IF($G35=U$1,$D35,"") | V22: =IF($G36=V$1,$D36,"") | W22: =CONCATENATE(H22," ",I22," ",J22," ",K22," ",L22," ",M22," ",N22," ",O22," ",P22," ",Q22," ",R22," ",S22," ",T22," ",U22," ",V22)
A23: =C23=D23 -> FALSE | B23: =B22+1 -> 22 | C23: Project Management Fundamental Terms | D23: Physical environment | E23: =LEN(D23) -> 20 | F23: 1 | G23: =IF(F23=1,1,G22+1) -> 1 | H23: =IF($G23=H$1,$D23,"") -> Physical environment | I23: =IF($G24=I$1,$D24,"") -> The physical structure and surroundings that affect a project’s work. | J23: =IF($G25=J$1,$D25,"") | K23: =IF($G26=K$1,$D26,"") | L23: =IF($G27=L$1,$D27,"") | M23: =IF($G28=M$1,$D28,"") | N23: =IF($G29=N$1,$D29,"") | O23: =IF($G30=O$1,$D30,"") | P23: =IF($G31=P$1,$D31,"") | Q23: =IF($G32=Q$1,$D32,"") | R23: =IF($G33=R$1,$D33,"") | S23: =IF($G34=S$1,$D34,"") | T23: =IF($G35=T$1,$D35,"") | U23: =IF($G36=U$1,$D36,"") | V23: =IF($G37=V$1,$D37,"") | W23: =CONCATENATE(H23," ",I23," ",J23," ",K23," ",L23," ",M23," ",N23," ",O23," ",P23," ",Q23," ",R23," ",S23," ",T23," ",U23," ",V23) -> Physical environment The physical structure and surroundings that affect a project’s work.
A24: =C24=D24 -> FALSE | B24: =B23+1 -> 23 | C24: Project Management Fundamental Terms | D24: The physical structure and surroundings that affect a project’s work. | E24: =LEN(D24) -> 69 | G24: =IF(F24=1,1,G23+1) -> 2 | H24: =IF($G24=H$1,$D24,"") | I24: =IF($G25=I$1,$D25,"") | J24: =IF($G26=J$1,$D26,"") | K24: =IF($G27=K$1,$D27,"") | L24: =IF($G28=L$1,$D28,"") | M24: =IF($G29=M$1,$D29,"") | N24: =IF($G30=N$1,$D30,"") | O24: =IF($G31=O$1,$D31,"") | P24: =IF($G32=P$1,$D32,"") | Q24: =IF($G33=Q$1,$D33,"") | R24: =IF($G34=R$1,$D34,"") | S24: =IF($G35=S$1,$D35,"") | T24: =IF($G36=T$1,$D36,"") | U24: =IF($G37=U$1,$D37,"") | V24: =IF($G38=V$1,$D38,"") | W24: =CONCATENATE(H24," ",I24," ",J24," ",K24," ",L24," ",M24," ",N24," ",O24," ",P24," ",Q24," ",R24," ",S24," ",T24," ",U24," ",V24)
A25: =C25=D25 -> FALSE | B25: =B24+1 -> 24 | C25: Project Management Fundamental Terms | D25: Process groups | E25: =LEN(D25) -> 14 | F25: 1 | G25: =IF(F25=1,1,G24+1) -> 1 | H25: =IF($G25=H$1,$D25,"") -> Process groups | I25: =IF($G26=I$1,$D26,"") -> A collection of related processes in project management. There are five process groups and 49 project management processes. The five process groups are Initiating, Planning, Executing, Monitoring and Controlling, and Closing. | J25: =IF($G27=J$1,$D27,"") | K25: =IF($G28=K$1,$D28,"") | L25: =IF($G29=L$1,$D29,"") | M25: =IF($G30=M$1,$D30,"") | N25: =IF($G31=N$1,$D31,"") | O25: =IF($G32=O$1,$D32,"") | P25: =IF($G33=P$1,$D33,"") | Q25: =IF($G34=Q$1,$D34,"") | R25: =IF($G35=R$1,$D35,"") | S25: =IF($G36=S$1,$D36,"") | T25: =IF($G37=T$1,$D37,"") | U25: =IF($G38=U$1,$D38,"") | V25: =IF($G39=V$1,$D39,"") | W25: =CONCATENATE(H25," ",I25," ",J25," ",K25," ",L25," ",M25," ",N25," ",O25," ",P25," ",Q25," ",R25," ",S25," ",T25," ",U25," ",V25) -> Process groups A collection of related processes in project management. There are five process groups and 49 project management processes. The five process groups are Initiating, Planning, Executing, Monitoring and Controlling, and Closing.
A26: =C26=D26 -> FALSE | B26: =B25+1 -> 25 | C26: Project Management Fundamental Terms | D26: A collection of related processes in project management. There are five process groups and 49 project management processes. The five process groups are Initiating, Planning, Executing, Monitoring and Controlling, and Closing. | E26: =LEN(D26) -> 225 | G26: =IF(F26=1,1,G25+1) -> 2 | H26: =IF($G26=H$1,$D26,"") | I26: =IF($G27=I$1,$D27,"") | J26: =IF($G28=J$1,$D28,"") | K26: =IF($G29=K$1,$D29,"") | L26: =IF($G30=L$1,$D30,"") | M26: =IF($G31=M$1,$D31,"") | N26: =IF($G32=N$1,$D32,"") | O26: =IF($G33=O$1,$D33,"") | P26: =IF($G34=P$1,$D34,"") | Q26: =IF($G35=Q$1,$D35,"") | R26: =IF($G36=R$1,$D36,"") | S26: =IF($G37=S$1,$D37,"") | T26: =IF($G38=T$1,$D38,"") | U26: =IF($G39=U$1,$D39,"") | V26: =IF($G40=V$1,$D40,"") | W26: =CONCATENATE(H26," ",I26," ",J26," ",K26," ",L26," ",M26," ",N26," ",O26," ",P26," ",Q26," ",R26," ",S26," ",T26," ",U26," ",V26)
A27: =C27=D27 -> FALSE | B27: =B26+1 -> 26 | C27: Project Management Fundamental Terms | D27: Program | E27: =LEN(D27) -> 7 | F27: 1 | G27: =IF(F27=1,1,G26+1) -> 1 | H27: =IF($G27=H$1,$D27,"") -> Program | I27: =IF($G28=I$1,$D28,"") -> A collection of related projects working in unison toward a common deliverable. | J27: =IF($G29=J$1,$D29,"") | K27: =IF($G30=K$1,$D30,"") | L27: =IF($G31=L$1,$D31,"") | M27: =IF($G32=M$1,$D32,"") | N27: =IF($G33=N$1,$D33,"") | O27: =IF($G34=O$1,$D34,"") | P27: =IF($G35=P$1,$D35,"") | Q27: =IF($G36=Q$1,$D36,"") | R27: =IF($G37=R$1,$D37,"") | S27: =IF($G38=S$1,$D38,"") | T27: =IF($G39=T$1,$D39,"") | U27: =IF($G40=U$1,$D40,"") | V27: =IF($G41=V$1,$D41,"") | W27: =CONCATENATE(H27," ",I27," ",J27," ",K27," ",L27," ",M27," ",N27," ",O27," ",P27," ",Q27," ",R27," ",S27," ",T27," ",U27," ",V27) -> Program A collection of related projects working in unison toward a common deliverable.
A28: =C28=D28 -> FALSE | B28: =B27+1 -> 27 | C28: Project Management Fundamental Terms | D28: A collection of related projects working in unison toward a common deliverable. | E28: =LEN(D28) -> 79 | G28: =IF(F28=1,1,G27+1) -> 2 | H28: =IF($G28=H$1,$D28,"") | I28: =IF($G29=I$1,$D29,"") | J28: =IF($G30=J$1,$D30,"") | K28: =IF($G31=K$1,$D31,"") | L28: =IF($G32=L$1,$D32,"") | M28: =IF($G33=M$1,$D33,"") | N28: =IF($G34=N$1,$D34,"") | O28: =IF($G35=O$1,$D35,"") | P28: =IF($G36=P$1,$D36,"") | Q28: =IF($G37=Q$1,$D37,"") | R28: =IF($G38=R$1,$D38,"") | S28: =IF($G39=S$1,$D39,"") | T28: =IF($G40=T$1,$D40,"") | U28: =IF($G41=U$1,$D41,"") | V28: =IF($G42=V$1,$D42,"") | W28: =CONCATENATE(H28," ",I28," ",J28," ",K28," ",L28," ",M28," ",N28," ",O28," ",P28," ",Q28," ",R28," ",S28," ",T28," ",U28," ",V28)
A29: =C29=D29 -> FALSE | B29: =B28+1 -> 28 | C29: Project Management Fundamental Terms | D29: Progressive elaboration | E29: =LEN(D29) -> 23 | F29: 1 | G29: =IF(F29=1,1,G28+1) -> 1 | H29: =IF($G29=H$1,$D29,"") -> Progressive elaboration | I29: =IF($G30=I$1,$D30,"") -> The process of gathering project details. This process uses deductive reasoning, logic, and a series of information-gathering techniques to identify details about a project, product, or solution. | J29: =IF($G31=J$1,$D31,"") | K29: =IF($G32=K$1,$D32,"") | L29: =IF($G33=L$1,$D33,"") | M29: =IF($G34=M$1,$D34,"") | N29: =IF($G35=N$1,$D35,"") | O29: =IF($G36=O$1,$D36,"") | P29: =IF($G37=P$1,$D37,"") | Q29: =IF($G38=Q$1,$D38,"") | R29: =IF($G39=R$1,$D39,"") | S29: =IF($G40=S$1,$D40,"") | T29: =IF($G41=T$1,$D41,"") | U29: =IF($G42=U$1,$D42,"") | V29: =IF($G43=V$1,$D43,"") | W29: =CONCATENATE(H29," ",I29," ",J29," ",K29," ",L29," ",M29," ",N29," ",O29," ",P29," ",Q29," ",R29," ",S29," ",T29," ",U29," ",V29) -> Progressive elaboration The process of gathering project details. This process uses deductive reasoning, logic, and a series of information-gathering techniques to identify details about a project, product, or solution.
A30: =C30=D30 -> FALSE | B30: =B29+1 -> 29 | C30: Project Management Fundamental Terms | D30: The process of gathering project details. This process uses deductive reasoning, logic, and a series of information-gathering techniques to identify details about a project, product, or solution. | E30: =LEN(D30) -> 195 | G30: =IF(F30=1,1,G29+1) -> 2 | H30: =IF($G30=H$1,$D30,"") | I30: =IF($G31=I$1,$D31,"") | J30: =IF($G32=J$1,$D32,"") | K30: =IF($G33=K$1,$D33,"") | L30: =IF($G34=L$1,$D34,"") | M30: =IF($G35=M$1,$D35,"") | N30: =IF($G36=N$1,$D36,"") | O30: =IF($G37=O$1,$D37,"") | P30: =IF($G38=P$1,$D38,"") | Q30: =IF($G39=Q$1,$D39,"") | R30: =IF($G40=R$1,$D40,"") | S30: =IF($G41=S$1,$D41,"") | T30: =IF($G42=T$1,$D42,"") | U30: =IF($G43=U$1,$D43,"") | V30: =IF($G44=V$1,$D44,"") | W30: =CONCATENATE(H30," ",I30," ",J30," ",K30," ",L30," ",M30," ",N30," ",O30," ",P30," ",Q30," ",R30," ",S30," ",T30," ",U30," ",V30)
A31: =C31=D31 -> FALSE | B31: =B30+1 -> 30 | C31: Project Management Fundamental Terms | D31: Project | E31: =LEN(D31) -> 7 | F31: 1 | G31: =IF(F31=1,1,G30+1) -> 1 | H31: =IF($G31=H$1,$D31,"") -> Project | I31: =IF($G32=I$1,$D32,"") -> A temporary endeavor to create a unique product, service, or result. The end result of a project is also called a deliverable. | J31: =IF($G33=J$1,$D33,"") | K31: =IF($G34=K$1,$D34,"") | L31: =IF($G35=L$1,$D35,"") | M31: =IF($G36=M$1,$D36,"") | N31: =IF($G37=N$1,$D37,"") | O31: =IF($G38=O$1,$D38,"") | P31: =IF($G39=P$1,$D39,"") | Q31: =IF($G40=Q$1,$D40,"") | R31: =IF($G41=R$1,$D41,"") | S31: =IF($G42=S$1,$D42,"") | T31: =IF($G43=T$1,$D43,"") | U31: =IF($G44=U$1,$D44,"") | V31: =IF($G45=V$1,$D45,"") | W31: =CONCATENATE(H31," ",I31," ",J31," ",K31," ",L31," ",M31," ",N31," ",O31," ",P31," ",Q31," ",R31," ",S31," ",T31," ",U31," ",V31) -> Project A temporary endeavor to create a unique product, service, or result. The end result of a project is also called a deliverable.
A32: =C32=D32 -> FALSE | B32: =B31+1 -> 31 | C32: Project Management Fundamental Terms | D32: A temporary endeavor to create a unique product, service, or result. The end result of a project is also called a deliverable. | E32: =LEN(D32) -> 126 | G32: =IF(F32=1,1,G31+1) -> 2 | H32: =IF($G32=H$1,$D32,"") | I32: =IF($G33=I$1,$D33,"") | J32: =IF($G34=J$1,$D34,"") | K32: =IF($G35=K$1,$D35,"") | L32: =IF($G36=L$1,$D36,"") | M32: =IF($G37=M$1,$D37,"") | N32: =IF($G38=N$1,$D38,"") | O32: =IF($G39=O$1,$D39,"") | P32: =IF($G40=P$1,$D40,"") | Q32: =IF($G41=Q$1,$D41,"") | R32: =IF($G42=R$1,$D42,"") | S32: =IF($G43=S$1,$D43,"") | T32: =IF($G44=T$1,$D44,"") | U32: =IF($G45=U$1,$D45,"") | V32: =IF($G46=V$1,$D46,"") | W32: =CONCATENATE(H32," ",I32," ",J32," ",K32," ",L32," ",M32," ",N32," ",O32," ",P32," ",Q32," ",R32," ",S32," ",T32," ",U32," ",V32)
A33: =C33=D33 -> FALSE | B33: =B32+1 -> 32 | C33: Project Management Fundamental Terms | D33: Project benefits management plan | E33: =LEN(D33) -> 32 | F33: 1 | G33: =IF(F33=1,1,G32+1) -> 1 | H33: =IF($G33=H$1,$D33,"") -> Project benefits management plan | I33: =IF($G34=I$1,$D34,"") -> A documented created and maintained by the project sponsor and the project manager. The project benefits management plan defines what benefits the project will create, when the benefits will be realized, and how the benefits will be measured. | J33: =IF($G35=J$1,$D35,"") | K33: =IF($G36=K$1,$D36,"") | L33: =IF($G37=L$1,$D37,"") | M33: =IF($G38=M$1,$D38,"") | N33: =IF($G39=N$1,$D39,"") | O33: =IF($G40=O$1,$D40,"") | P33: =IF($G41=P$1,$D41,"") | Q33: =IF($G42=Q$1,$D42,"") | R33: =IF($G43=R$1,$D43,"") | S33: =IF($G44=S$1,$D44,"") | T33: =IF($G45=T$1,$D45,"") | U33: =IF($G46=U$1,$D46,"") | V33: =IF($G47=V$1,$D47,"") | W33: =CONCATENATE(H33," ",I33," ",J33," ",K33," ",L33," ",M33," ",N33," ",O33," ",P33," ",Q33," ",R33," ",S33," ",T33," ",U33," ",V33) -> Project benefits management plan A documented created and maintained by the project sponsor and the project manager. The project benefits management plan defines what benefits the project will create, when the benefits will be realized, and how the benefits will be measured.
A34: =C34=D34 -> FALSE | B34: =B33+1 -> 33 | C34: Project Management Fundamental Terms | D34: A documented created and maintained by the project sponsor and the project manager. The project benefits management plan defines what benefits the project will create, when the benefits will be realized, and how the benefits will be measured. | E34: =LEN(D34) -> 242 | G34: =IF(F34=1,1,G33+1) -> 2 | H34: =IF($G34=H$1,$D34,"") | I34: =IF($G35=I$1,$D35,"") | J34: =IF($G36=J$1,$D36,"") | K34: =IF($G37=K$1,$D37,"") | L34: =IF($G38=L$1,$D38,"") | M34: =IF($G39=M$1,$D39,"") | N34: =IF($G40=N$1,$D40,"") | O34: =IF($G41=O$1,$D41,"") | P34: =IF($G42=P$1,$D42,"") | Q34: =IF($G43=Q$1,$D43,"") | R34: =IF($G44=R$1,$D44,"") | S34: =IF($G45=S$1,$D45,"") | T34: =IF($G46=T$1,$D46,"") | U34: =IF($G47=U$1,$D47,"") | V34: =IF($G48=V$1,$D48,"") | W34: =CONCATENATE(H34," ",I34," ",J34," ",K34," ",L34," ",M34," ",N34," ",O34," ",P34," ",Q34," ",R34," ",S34," ",T34," ",U34," ",V34)
A35: =C35=D35 -> FALSE | B35: =B34+1 -> 34 | C35: Project Management Fundamental Terms | D35: Project business case | E35: =LEN(D35) -> 21 | F35: 1 | G35: =IF(F35=1,1,G34+1) -> 1 | H35: =IF($G35=H$1,$D35,"") -> Project business case | I35: =IF($G36=I$1,$D36,"") -> Created and maintained by the project sponsor and shows the financial validity of why a project is chartered and launched within the organization. Typically, the project business case is created before the launch of the project and may be used as a go/no-go decision point. | J35: =IF($G37=J$1,$D37,"") | K35: =IF($G38=K$1,$D38,"") | L35: =IF($G39=L$1,$D39,"") | M35: =IF($G40=M$1,$D40,"") | N35: =IF($G41=N$1,$D41,"") | O35: =IF($G42=O$1,$D42,"") | P35: =IF($G43=P$1,$D43,"") | Q35: =IF($G44=Q$1,$D44,"") | R35: =IF($G45=R$1,$D45,"") | S35: =IF($G46=S$1,$D46,"") | T35: =IF($G47=T$1,$D47,"") | U35: =IF($G48=U$1,$D48,"") | V35: =IF($G49=V$1,$D49,"") | W35: =CONCATENATE(H35," ",I35," ",J35," ",K35," ",L35," ",M35," ",N35," ",O35," ",P35," ",Q35," ",R35," ",S35," ",T35," ",U35," ",V35) -> Project business case Created and maintained by the project sponsor and shows the financial validity of why a project is chartered and launched within the organization. Typically, the project business case is created before the launch of the project and may be used as a go/no-go decision point.
A36: =C36=D36 -> FALSE | B36: =B35+1 -> 35 | C36: Project Management Fundamental Terms | D36: Created and maintained by the project sponsor and shows the financial validity of why a project is chartered and launched within the organization. Typically, the project business case is created before the launch of the project and may be used as a go/no-go decision point. | E36: =LEN(D36) -> 273 | G36: =IF(F36=1,1,G35+1) -> 2 | H36: =IF($G36=H$1,$D36,"") | I36: =IF($G37=I$1,$D37,"") | J36: =IF($G38=J$1,$D38,"") | K36: =IF($G39=K$1,$D39,"") | L36: =IF($G40=L$1,$D40,"") | M36: =IF($G41=M$1,$D41,"") | N36: =IF($G42=N$1,$D42,"") | O36: =IF($G43=O$1,$D43,"") | P36: =IF($G44=P$1,$D44,"") | Q36: =IF($G45=Q$1,$D45,"") | R36: =IF($G46=R$1,$D46,"") | S36: =IF($G47=S$1,$D47,"") | T36: =IF($G48=T$1,$D48,"") | U36: =IF($G49=U$1,$D49,"") | V36: =IF($G50=V$1,$D50,"") | W36: =CONCATENATE(H36," ",I36," ",J36," ",K36," ",L36," ",M36," ",N36," ",O36," ",P36," ",Q36," ",R36," ",S36," ",T36," ",U36," ",V36)
A37: =C37=D37 -> FALSE | B37: =B36+1 -> 36 | C37: Project Management Fundamental Terms | D37: Project environment | E37: =LEN(D37) -> 19 | F37: 1 | G37: =IF(F37=1,1,G36+1) -> 1 | H37: =IF($G37=H$1,$D37,"") -> Project environment | I37: =IF($G38=I$1,$D38,"") -> The location and culture of the environment where the project work will reside. The project environment includes the social, economic, and environmental variables the project must work with or around. | J37: =IF($G39=J$1,$D39,"") | K37: =IF($G40=K$1,$D40,"") | L37: =IF($G41=L$1,$D41,"") | M37: =IF($G42=M$1,$D42,"") | N37: =IF($G43=N$1,$D43,"") | O37: =IF($G44=O$1,$D44,"") | P37: =IF($G45=P$1,$D45,"") | Q37: =IF($G46=Q$1,$D46,"") | R37: =IF($G47=R$1,$D47,"") | S37: =IF($G48=S$1,$D48,"") | T37: =IF($G49=T$1,$D49,"") | U37: =IF($G50=U$1,$D50,"") | V37: =IF($G51=V$1,$D51,"") | W37: =CONCATENATE(H37," ",I37," ",J37," ",K37," ",L37," ",M37," ",N37," ",O37," ",P37," ",Q37," ",R37," ",S37," ",T37," ",U37," ",V37) -> Project environment The location and culture of the environment where the project work will reside. The project environment includes the social, economic, and environmental variables the project must work with or around.
A38: =C38=D38 -> FALSE | B38: =B37+1 -> 37 | C38: Project Management Fundamental Terms | D38: The location and culture of the environment where the project work will reside. The project environment includes the social, economic, and environmental variables the project must work with or around. | E38: =LEN(D38) -> 200 | G38: =IF(F38=1,1,G37+1) -> 2 | H38: =IF($G38=H$1,$D38,"") | I38: =IF($G39=I$1,$D39,"") | J38: =IF($G40=J$1,$D40,"") | K38: =IF($G41=K$1,$D41,"") | L38: =IF($G42=L$1,$D42,"") | M38: =IF($G43=M$1,$D43,"") | N38: =IF($G44=N$1,$D44,"") | O38: =IF($G45=O$1,$D45,"") | P38: =IF($G46=P$1,$D46,"") | Q38: =IF($G47=Q$1,$D47,"") | R38: =IF($G48=R$1,$D48,"") | S38: =IF($G49=S$1,$D49,"") | T38: =IF($G50=T$1,$D50,"") | U38: =IF($G51=U$1,$D51,"") | V38: =IF($G52=V$1,$D52,"") | W38: =CONCATENATE(H38," ",I38," ",J38," ",K38," ",L38," ",M38," ",N38," ",O38," ",P38," ",Q38," ",R38," ",S38," ",T38," ",U38," ",V38)
A39: =C39=D39 -> FALSE | B39: =B38+1 -> 38 | C39: Project Management Fundamental Terms | D39: Project Management Institute (PMI) | E39: =LEN(D39) -> 34 | F39: 1 | G39: =IF(F39=1,1,G38+1) -> 1 | H39: =IF($G39=H$1,$D39,"") -> Project Management Institute (PMI) | I39: =IF($G40=I$1,$D40,"") -> An organization of project management professionals from around the world, supporting and promoting the careers, values, and concerns of project managers. | J39: =IF($G41=J$1,$D41,"") | K39: =IF($G42=K$1,$D42,"") | L39: =IF($G43=L$1,$D43,"") | M39: =IF($G44=M$1,$D44,"") | N39: =IF($G45=N$1,$D45,"") | O39: =IF($G46=O$1,$D46,"") | P39: =IF($G47=P$1,$D47,"") | Q39: =IF($G48=Q$1,$D48,"") | R39: =IF($G49=R$1,$D49,"") | S39: =IF($G50=S$1,$D50,"") | T39: =IF($G51=T$1,$D51,"") | U39: =IF($G52=U$1,$D52,"") | V39: =IF($G53=V$1,$D53,"") | W39: =CONCATENATE(H39," ",I39," ",J39," ",K39," ",L39," ",M39," ",N39," ",O39," ",P39," ",Q39," ",R39," ",S39," ",T39," ",U39," ",V39) -> Project Management Institute (PMI) An organization of project management professionals from around the world, supporting and promoting the careers, values, and concerns of project managers.
A40: =C40=D40 -> FALSE | B40: =B39+1 -> 39 | C40: Project Management Fundamental Terms | D40: An organization of project management professionals from around the world, supporting and promoting the careers, values, and concerns of project managers. | E40: =LEN(D40) -> 154 | G40: =IF(F40=1,1,G39+1) -> 2 | H40: =IF($G40=H$1,$D40,"") | I40: =IF($G41=I$1,$D41,"") | J40: =IF($G42=J$1,$D42,"") | K40: =IF($G43=K$1,$D43,"") | L40: =IF($G44=L$1,$D44,"") | M40: =IF($G45=M$1,$D45,"") | N40: =IF($G46=N$1,$D46,"") | O40: =IF($G47=O$1,$D47,"") | P40: =IF($G48=P$1,$D48,"") | Q40: =IF($G49=Q$1,$D49,"") | R40: =IF($G50=R$1,$D50,"") | S40: =IF($G51=S$1,$D51,"") | T40: =IF($G52=T$1,$D52,"") | U40: =IF($G53=U$1,$D53,"") | V40: =IF($G54=V$1,$D54,"") | W40: =CONCATENATE(H40," ",I40," ",J40," ",K40," ",L40," ",M40," ",N40," ",O40," ",P40," ",Q40," ",R40," ",S40," ",T40," ",U40," ",V40)
...

Sheet Summary
A3: Row Labels | B3: Count of Term
A4: Project Communications Management Terms | B4: 26
A5: Project Integration Management Terms | B5: 40
A6: Project Management Fundamental Terms | B6: 26
A7: Project Manager Role | B7: 13
A8: Project Quality Management Terms | B8: 30
A9: Project Resources Management Terms | B9: 28
A10: Project Risk Management Terms | B10: 72
A11: Project Scope Management Terms | B11: 84
A12: Project Stakeholder Management Terms | B12: 16
A13: Grand Total | B13: 335

Sheet All
B2: 🧠 Core Domains (PMI Talent Triangle) | C2: 📚 PMBOK® Guide Knowledge Areas | D2: 📈 Performance Domains (PMBOK® 7th Edition) | E2: 🧩 Key Concepts to Master | F2: 📝 Exam Strategy
B3: 1. People – Leadership, team performance, conflict resolution, motivation | C3: These are traditional areas from earlier PMBOK editions, still relevant: | D3: These are broader areas of focus in modern PMP: | E3: Tailoring – Adapting methods to fit the project | F3: Situational Questions – Apply concepts to real scenarios
B4: 2. Process – Project management practices, tools, and techniques | C4: 1. Integration Management | D4: 1. Team | E4: Delivery Approaches – Predictive, Agile, Hybrid, etc. | F4: Agile & Hybrid Focus – Increasing emphasis on adaptive methods
B5: 3. Business Environment – Strategic alignment, compliance, value delivery | C5: 2. Scope Management | D5: 2. Stakeholders | E5: Principles – 12 guiding principles from PMBOK® 7 | F5: Ethics & Professional Conduct – PMI Code of Ethics
C6: 3. Schedule Management | D6: 3. Life Cycle & Development Approach | E6: Math & Formulas – Earned Value, PERT, ROI, etc.
C7: 4. Cost Management | D7: 4. Planning | E7: Scenarios – Real-world application of concepts
C8: 5. Quality Management | D8: 5. Project Work | E8: Manager Role – Leadership, decision-making, ethics
C9: 6. Resource Management | D9: 6. Delivery | E9: Fundamentals – Definitions, roles, processes
C10: 7. Communications Management | D10: 7. Measurement
C11: 8. Risk Management | D11: 8. Uncertainty
C12: 9. Procurement Management
C13: 10. Stakeholder Management

Sheet PMBOK
F1: APPENDIX X1
B2: THE STANDARD FOR PROJECT MANAGEMENT | D2: A GUIDE TO THE PROJECT MANAGEMENT | F2: CONTRIBUTORS AND REVIEWERS OF
B3: 1 INTRODUCTION...................................................................................3 | D3: BODY OF KNOWLEDGE (PMBOK® GUIDE) | F3: THE STANDARD FOR PROJECT MANAGEMENT AND
B4: 1.1 Purpose of The Standard for Project Management......................3 | D4: 1. INTRODUCTION..................................................................................3 | F4: A GUIDE TO THE PROJECT MANAGEMENT BODY
B5: 1.2 Key Terms and Concepts.............................................................4 | D5: 1.1 Structure of the PMBOK® Guide................................................3 | F5: OF KNOWLEDGE – SEVENTH EDITION...............................................197
B6: 1.3 Audience for this Standard..........................................................5 | D6: 1.2 Relationship of the PMBOK® Guide | F6: X1.1 Contributors........................................................................197
B7: 2 A SYSTEM FOR VALUE DELIVERY........................................................7 | D7: and The Standard for Project Management................................4 | F7: X1.2 PMI Staff.............................................................................206
B8: 2.1 Creating Value.............................................................................7 | D8: 1.3 Changes to the PMBOK® Guide.................................................6 | F8: APPENDIX X2
B9: 2.1.1 Value Delivery Components...............................................8 | D9: 1.4 Relationship to PMIstandards+..................................................6 | F9: SPONSOR.............................................................................................207
B10: 2.1.2 Information Flow.............................................................11 | D10: 2. PROJECT PERFORMANCE DOMAINS..................................................7 | F10: X2.1 Introduction........................................................................207
B11: 2.2 Organizational Governance Systems.........................................12 | D11: 2.1 Stakeholder Performance Domain.............................................8 | F11: X2.2 The Sponsor Role................................................................207
B12: 2.3 Functions Associated with Projects...........................................12 | D12: 2.1.1 Stakeholder Engagement...............................................10 | F12: X2.3 Lack of Engagement............................................................208
B13: 2.3.1 Provide Oversight and Coordination................................13 | D13: 2.1.2 Interactions with Other Performance Domains...............14 | F13: X2.4 Sponsor Behaviors...............................................................209
... B38: References.......................................................................................60 | D38: 2.4.3 Project Team Composition and Structure........................63 | F38: X5.3 Research for The Standard for Project Management...........228
D39: 2.4.4 Communication..............................................................64 | F39: X5.4 Standard Development Process...........................................229
B40: List of Figures and Tables | D40: 2.4.5 Physical Resources.........................................................65 | F40: X5.5 Validating the Standard.......................................................230
B41: THE STANDARD FOR PROJECT MANAGEMENT | D41: 2.4.6 Procurement..................................................................65 | F41: X5.6 Summary.............................................................................232
B42: Figure 2-1. Example of a System for Value Delivery............................9 | D42: 2.4.7 Changes.........................................................................66 | F42: GLOSSARY...........................................................................................233
B43: Figure 2-2. Components of a Sample System for Value Delivery.......10 | D43: 2.4.8 Metrics...........................................................................66 | F43: 1. Inclusions and Exclusions...........................................................233
B44: Figure 2-3. Example of Information Flow..........................................11 | D44: 2.4.9 Alignment......................................................................67 | F44: 2. Common Acronyms...................................................................234
B45: Figure 2-4. Sample Product Life Cycle...............................................19 | D45: 2.4.10 Interactions with Other Performance Domains...............67 | F45: 3. Definitions.................................................................................235
B46: Figure 3-1. Overlap of Project Management | D46: 2.4.11 Checking Results............................................................68 | F46: INDEX..................................................................................................255
B47: and General Management Principles...............................22 | D47: 2.5 Project Work Performance Domain...........................................69
B48: Figure 3-2. Be a Diligent, Respectful, and Caring Steward................24 | D48: 2.5.1 Project Processes...........................................................71
B49: Figure 3-3. Create a Collaborative Project Team Environment...........28 | D49: 2.5.2 Balancing Competing Constraints...................................72
B50: Figure 3-4. Effectively Engage with Stakeholders.............................31 | D50: 2.5.3 Maintaining Project Team Focus.....................................73
B51: Figure 3-5. Focus on Value................................................................34 | D51: 2.5.4 Project Communications and Engagement.....................73
B52: Figure 3-6. Recognize, Evaluate, and Respond | D52: 2.5.5 Managing Physical Resources.........................................73
B53: to System Interactions.....................................................37 | D53: 2.5.6 Working with Procurements...........................................74
B54: Figure 3-7. Demonstrate Leadership Behaviors.................................40 | D54: 2.5.7 Monitoring New Work and Changes...............................76
B55: Figure 3-8. Tailor Based on Context..................................................44 | D55: 2.5.8 Learning throughout the Project....................................77
B56: Figure 3-9. Build Quality into Processes and Deliverables.................47 | D56: 2.5.9 Interactions with Other Performance Domains...............78
B57: Figure 3-10. Navigate Complexity.......................................................50 | D57: 2.5.10 Checking Results............................................................79
B58: Figure 3-11. Optimize Risk Responses.................................................53 | D58: 2.6 Delivery Performance Domain...................................................80
... B61: the Envisioned Future State............................................58 | D61: 2.6.3 Quality...........................................................................87
D62: 2.6.4 Suboptimal Outcomes....................................................91
D63: 2.6.5 Interactions with Other Performance Domains...............91
D64: 2.6.6 Checking Results............................................................92
D65: 2.7 Measurement Performance Domain...........................................93
D66: 2.7.1 Establishing Effective Measures.....................................95
...

Sheet Sheet9
H2: Module | I2: Pmism's
